<sdf version='1.7'>
  <world name='default'>
    <model name='ground_plane'>
      <static>1</static>
      <link name='link'>
        <collision name='collision'>
          <geometry>
            <plane>
              <normal>0 0 1</normal>
              <size>100 100</size>
            </plane>
          </geometry>
          <surface>
            <contact>
              <collide_bitmask>65535</collide_bitmask>
              <ode/>
            </contact>
            <friction>
              <ode>
                <mu>100</mu>
                <mu2>50</mu2>
              </ode>
              <torsional>
                <ode/>
              </torsional>
            </friction>
            <bounce/>
          </surface>
          <max_contacts>10</max_contacts>
        </collision>
        <visual name='visual'>
          <cast_shadows>0</cast_shadows>
          <geometry>
            <plane>
              <normal>0 0 1</normal>
              <size>100 100</size>
            </plane>
          </geometry>
          <material>
            <script>
              <uri>file://media/materials/scripts/gazebo.material</uri>
              <name>Gazebo/Grey</name>
            </script>
          </material>
        </visual>
        <self_collide>0</self_collide>
        <enable_wind>0</enable_wind>
        <kinematic>0</kinematic>
      </link>
    </model>
    <light name='sun' type='directional'>
      <cast_shadows>1</cast_shadows>
      <pose>0 0 10 0 -0 0</pose>
      <diffuse>0.8 0.8 0.8 1</diffuse>
      <specular>0.2 0.2 0.2 1</specular>
      <attenuation>
        <range>1000</range>
        <constant>0.9</constant>
        <linear>0.01</linear>
        <quadratic>0.001</quadratic>
      </attenuation>
      <direction>-0.5 0.1 -0.9</direction>
      <spot>
        <inner_angle>0</inner_angle>
        <outer_angle>0</outer_angle>
        <falloff>0</falloff>
      </spot>
    </light>
    <model name='table1'>
      <static>1</static>
      <link name='link'>
        <collision name='surface'>
          <pose>0 0 0.755 0 -0 0</pose>
          <geometry>
            <box>
              <size>0.913 0.913 0.04</size>
            </box>
          </geometry>
          <max_contacts>10</max_contacts>
          <surface>
            <contact>
              <ode/>
            </contact>
            <bounce/>
            <friction>
              <torsional>
                <ode/>
              </torsional>
              <ode/>
            </friction>
          </surface>
        </collision>
        <collision name='column'>
          <pose>0 0 0.37 0 -0 0</pose>
          <geometry>
            <box>
              <size>0.042 0.042 0.74</size>
            </box>
          </geometry>
          <max_contacts>10</max_contacts>
          <surface>
            <contact>
              <ode/>
            </contact>
            <bounce/>
            <friction>
              <torsional>
                <ode/>
              </torsional>
              <ode/>
            </friction>
          </surface>
        </collision>
        <collision name='base'>
          <pose>0 0 0.02 0 -0 0</pose>
          <geometry>
            <box>
              <size>0.56 0.56 0.04</size>
            </box>
          </geometry>
          <max_contacts>10</max_contacts>
          <surface>
            <contact>
              <ode/>
            </contact>
            <bounce/>
            <friction>
              <torsional>
                <ode/>
              </torsional>
              <ode/>
            </friction>
          </surface>
        </collision>
        <visual name='visual'>
          <geometry>
            <mesh>
              <uri>model://cafe_table/meshes/cafe_table.dae</uri>
            </mesh>
          </geometry>
        </visual>
        <self_collide>0</self_collide>
        <enable_wind>0</enable_wind>
        <kinematic>0</kinematic>
      </link>
      <pose>1 0 -0.08 0 -0 0</pose>
    </model>
    <gravity>0 0 -9.8</gravity>
    <magnetic_field>6e-06 2.3e-05 -4.2e-05</magnetic_field>
    <atmosphere type='adiabatic'/>
    <physics type='ode'>
      <max_step_size>0.001</max_step_size>
      <real_time_factor>1</real_time_factor>
      <real_time_update_rate>1000</real_time_update_rate>
    </physics>
    <scene>
      <ambient>0.4 0.4 0.4 1</ambient>
      <background>0.7 0.7 0.7 1</background>
      <shadows>1</shadows>
    </scene>
    <wind/>
    <spherical_coordinates>
      <surface_model>EARTH_WGS84</surface_model>
      <latitude_deg>0</latitude_deg>
      <longitude_deg>0</longitude_deg>
      <elevation>0</elevation>
      <heading_deg>0</heading_deg>
    </spherical_coordinates>
    <model name='fetch'>
      <link name='base_link'>
        <inertial>
          <pose>-0.028327 0.000912 0.103535 0 -0 0</pose>
          <mass>83.4572</mass>
          <inertia>
            <ixx>10.2084</ixx>
            <ixy>0.0213394</ixy>
            <ixz>1.10946</ixz>
            <iyy>10.4919</iyy>
            <iyz>-0.0326219</iyz>
            <izz>5.3614</izz>
          </inertia>
        </inertial>
        <collision name='base_link_collision'>
          <pose>0 0 0 0 -0 0</pose>
          <geometry>
            <mesh>
              <scale>1 1 1</scale>
              <uri>/home/ros/workspace/src/fetch_ros/fetch_description/meshes/base_link_collision.STL</uri>
            </mesh>
          </geometry>
          <surface>
            <contact>
              <ode>
                <kp>1e+08</kp>
                <kd>10</kd>
                <max_vel>10</max_vel>
                <min_depth>0.0005</min_depth>
              </ode>
            </contact>
            <friction>
              <ode>
                <mu>0.1</mu>
                <mu2>0.1</mu2>
                <fdir1>1 0 0</fdir1>
              </ode>
              <torsional>
                <ode/>
              </torsional>
            </friction>
            <bounce/>
          </surface>
          <max_contacts>10</max_contacts>
        </collision>
        <collision name='base_link_fixed_joint_lump__bl_caster_link_collision_1'>
          <pose>-0.2 -0.12 0.055325 0 -0 0</pose>
          <geometry>
            <sphere>
              <radius>0.0601</radius>
            </sphere>
          </geometry>
          <surface>
            <contact>
              <ode>
                <kp>1e+08</kp>
                <kd>10</kd>
                <max_vel>10</max_vel>
                <min_depth>0.001</min_depth>
              </ode>
            </contact>
            <friction>
              <ode>
                <mu>0.1</mu>
                <mu2>0.1</mu2>
              </ode>
              <torsional>
                <ode/>
              </torsional>
            </friction>
            <bounce/>
          </surface>
          <max_contacts>10</max_contacts>
        </collision>
        <collision name='base_link_fixed_joint_lump__br_caster_link_collision_2'>
          <pose>-0.2 0.12 0.055325 0 -0 0</pose>
          <geometry>
            <sphere>
              <radius>0.0601</radius>
            </sphere>
          </geometry>
          <surface>
            <contact>
              <ode>
                <kp>1e+08</kp>
                <kd>10</kd>
                <max_vel>10</max_vel>
                <min_depth>0.001</min_depth>
              </ode>
            </contact>
            <friction>
              <ode>
                <mu>0.1</mu>
                <mu2>0.1</mu2>
              </ode>
              <torsional>
                <ode/>
              </torsional>
            </friction>
            <bounce/>
          </surface>
          <max_contacts>10</max_contacts>
        </collision>
        <collision name='base_link_fixed_joint_lump__estop_link_collision_3'>
          <pose>-0.12465 0.23892 0.31127 1.5708 -0 0</pose>
          <geometry>
            <mesh>
              <scale>1 1 1</scale>
              <uri>/home/ros/workspace/src/fetch_ros/fetch_description/meshes/estop_link.STL</uri>
            </mesh>
          </geometry>
          <surface>
            <contact>
              <ode/>
            </contact>
            <friction>
              <ode/>
              <torsional>
                <ode/>
              </torsional>
            </friction>
            <bounce/>
          </surface>
          <max_contacts>10</max_contacts>
        </collision>
        <collision name='base_link_fixed_joint_lump__fl_caster_link_collision_4'>
          <pose>0.15 0.12 0.055325 0 -0 0</pose>
          <geometry>
            <sphere>
              <radius>0.0601</radius>
            </sphere>
          </geometry>
          <surface>
            <contact>
              <ode>
                <kp>1e+08</kp>
                <kd>10</kd>
                <max_vel>10</max_vel>
                <min_depth>0.001</min_depth>
              </ode>
            </contact>
            <friction>
              <ode>
                <mu>0.1</mu>
                <mu2>0.1</mu2>
              </ode>
              <torsional>
                <ode/>
              </torsional>
            </friction>
            <bounce/>
          </surface>
          <max_contacts>10</max_contacts>
        </collision>
        <collision name='base_link_fixed_joint_lump__fr_caster_link_collision_5'>
          <pose>0.15 -0.12 0.055325 0 -0 0</pose>
          <geometry>
            <sphere>
              <radius>0.0601</radius>
            </sphere>
          </geometry>
          <surface>
            <contact>
              <ode>
                <kp>1e+08</kp>
                <kd>10</kd>
                <max_vel>10</max_vel>
                <min_depth>0.001</min_depth>
              </ode>
            </contact>
            <friction>
              <ode>
                <mu>0.1</mu>
                <mu2>0.1</mu2>
              </ode>
              <torsional>
                <ode/>
              </torsional>
            </friction>
            <bounce/>
          </surface>
          <max_contacts>10</max_contacts>
        </collision>
        <collision name='base_link_fixed_joint_lump__laser_link_collision_6'>
          <pose>0.235 0 0.2878 -3.14159 0 0</pose>
          <geometry>
            <mesh>
              <scale>1 1 1</scale>
              <uri>/home/ros/workspace/src/fetch_ros/fetch_description/meshes/laser_link.STL</uri>
            </mesh>
          </geometry>
          <surface>
            <contact>
              <ode/>
            </contact>
            <friction>
              <ode/>
              <torsional>
                <ode/>
              </torsional>
            </friction>
            <bounce/>
          </surface>
          <max_contacts>10</max_contacts>
        </collision>
        <collision name='base_link_fixed_joint_lump__torso_fixed_link_collision_7'>
          <pose>-0.086875 0 0.377425 0 -0 0</pose>
          <geometry>
            <mesh>
              <scale>1 1 1</scale>
              <uri>/home/ros/workspace/src/fetch_ros/fetch_description/meshes/torso_fixed_link.STL</uri>
            </mesh>
          </geometry>
          <max_contacts>10</max_contacts>
          <surface>
            <contact>
              <ode/>
            </contact>
            <bounce/>
            <friction>
              <torsional>
                <ode/>
              </torsional>
              <ode/>
            </friction>
          </surface>
        </collision>
        <visual name='base_link_visual'>
          <pose>0 0 0 0 -0 0</pose>
          <geometry>
            <mesh>
              <scale>1 1 1</scale>
              <uri>/home/ros/workspace/src/fetch_ros/fetch_description/meshes/base_link.dae</uri>
            </mesh>
          </geometry>
        </visual>
        <visual name='base_link_fixed_joint_lump__bl_caster_link_visual_1'>
          <pose>-0.2 -0.12 0.055325 0 -0 0</pose>
          <geometry>
            <sphere>
              <radius>0.0601</radius>
            </sphere>
          </geometry>
        </visual>
        <visual name='base_link_fixed_joint_lump__br_caster_link_visual_2'>
          <pose>-0.2 0.12 0.055325 0 -0 0</pose>
          <geometry>
            <sphere>
              <radius>0.0601</radius>
            </sphere>
          </geometry>
        </visual>
        <visual name='base_link_fixed_joint_lump__estop_link_visual_3'>
          <pose>-0.12465 0.23892 0.31127 1.5708 -0 0</pose>
          <geometry>
            <mesh>
              <scale>1 1 1</scale>
              <uri>/home/ros/workspace/src/fetch_ros/fetch_description/meshes/estop_link.dae</uri>
            </mesh>
          </geometry>
          <material>
            <script>
              <name>Gazebo/Red</name>
              <uri>file://media/materials/scripts/gazebo.material</uri>
            </script>
          </material>
        </visual>
        <visual name='base_link_fixed_joint_lump__fl_caster_link_visual_4'>
          <pose>0.15 0.12 0.055325 0 -0 0</pose>
          <geometry>
            <sphere>
              <radius>0.0601</radius>
            </sphere>
          </geometry>
        </visual>
        <visual name='base_link_fixed_joint_lump__fr_caster_link_visual_5'>
          <pose>0.15 -0.12 0.055325 0 -0 0</pose>
          <geometry>
            <sphere>
              <radius>0.0601</radius>
            </sphere>
          </geometry>
        </visual>
        <visual name='base_link_fixed_joint_lump__laser_link_visual_6'>
          <pose>0.235 0 0.2878 -3.14159 0 0</pose>
          <geometry>
            <mesh>
              <scale>1 1 1</scale>
              <uri>/home/ros/workspace/src/fetch_ros/fetch_description/meshes/laser_link.STL</uri>
            </mesh>
          </geometry>
        </visual>
        <visual name='base_link_fixed_joint_lump__torso_fixed_link_visual_7'>
          <pose>-0.086875 0 0.377425 0 -0 0</pose>
          <geometry>
            <mesh>
              <scale>1 1 1</scale>
              <uri>/home/ros/workspace/src/fetch_ros/fetch_description/meshes/torso_fixed_link.dae</uri>
            </mesh>
          </geometry>
        </visual>
        <sensor name='base_laser' type='ray'>
          <visualize>0</visualize>
          <update_rate>15</update_rate>
          <ray>
            <scan>
              <horizontal>
                <samples>662</samples>
                <resolution>1</resolution>
                <min_angle>-1.91986</min_angle>
                <max_angle>1.91986</max_angle>
              </horizontal>
              <vertical>
                <samples>1</samples>
                <min_angle>0</min_angle>
                <max_angle>0</max_angle>
              </vertical>
            </scan>
            <range>
              <min>0.05</min>
              <max>25</max>
              <resolution>0.01</resolution>
            </range>
            <noise>
              <type>gaussian</type>
              <mean>0</mean>
              <stddev>0.02</stddev>
            </noise>
          </ray>
          <plugin name='gazebo_ros_base_hokuyo_controller' filename='libgazebo_ros_laser.so'>
            <topicName>/base_scan</topicName>
            <frameName>laser_link</frameName>
            <robotNamespace>/</robotNamespace>
          </plugin>
          <pose>0.235 0 0.2878 -3.14159 -0 0</pose>
        </sensor>
        <self_collide>0</self_collide>
        <enable_wind>0</enable_wind>
        <kinematic>0</kinematic>
      </link>
      <joint name='l_wheel_joint' type='revolute'>
        <pose relative_to='base_link'>0.001291 0.18738 0.055325 0 -0 0</pose>
        <parent>base_link</parent>
        <child>l_wheel_link</child>
        <axis>
          <xyz>0 1 0</xyz>
          <limit>
            <effort>8.85</effort>
            <velocity>17.4</velocity>
            <lower>-1e+16</lower>
            <upper>1e+16</upper>
          </limit>
          <dynamics>
            <spring_reference>0</spring_reference>
            <spring_stiffness>0</spring_stiffness>
          </dynamics>
        </axis>
        <physics>
          <ode>
            <implicit_spring_damper>1</implicit_spring_damper>
            <cfm_damping>1</cfm_damping>
            <limit>
              <cfm>0</cfm>
              <erp>0.2</erp>
            </limit>
          </ode>
        </physics>
      </joint>
      <link name='l_wheel_link'>
        <pose relative_to='l_wheel_joint'>0 0 0 0 -0 0</pose>
        <inertial>
          <pose>0 0 0 0 -0 0</pose>
          <mass>4.3542</mass>
          <inertia>
            <ixx>0.0045</ixx>
            <ixy>0</ixy>
            <ixz>0</ixz>
            <iyy>0.005</iyy>
            <iyz>0</iyz>
            <izz>0.0045</izz>
          </inertia>
        </inertial>
        <collision name='l_wheel_link_collision'>
          <pose>0 0 0 0 -0 0</pose>
          <geometry>
            <mesh>
              <scale>1 1 1</scale>
              <uri>/home/ros/workspace/src/fetch_ros/fetch_description/meshes/l_wheel_link_collision.STL</uri>
            </mesh>
          </geometry>
          <surface>
            <contact>
              <ode>
                <kp>1e+06</kp>
                <kd>100</kd>
                <max_vel>1</max_vel>
                <min_depth>0.01</min_depth>
              </ode>
            </contact>
            <friction>
              <ode>
                <mu>1e+14</mu>
                <mu2>1e+14</mu2>
              </ode>
              <torsional>
                <ode/>
              </torsional>
            </friction>
            <bounce/>
          </surface>
          <max_contacts>10</max_contacts>
        </collision>
        <visual name='l_wheel_link_visual'>
          <pose>0 0 0 0 -0 0</pose>
          <geometry>
            <mesh>
              <scale>1 1 1</scale>
              <uri>/home/ros/workspace/src/fetch_ros/fetch_description/meshes/l_wheel_link.STL</uri>
            </mesh>
          </geometry>
          <material>
            <script>
              <name>Gazebo/Black</name>
              <uri>file://media/materials/scripts/gazebo.material</uri>
            </script>
          </material>
        </visual>
        <self_collide>0</self_collide>
        <enable_wind>0</enable_wind>
        <kinematic>0</kinematic>
      </link>
      <joint name='r_wheel_joint' type='revolute'>
        <pose relative_to='base_link'>0.001291 -0.18738 0.055325 0 -0 0</pose>
        <parent>base_link</parent>
        <child>r_wheel_link</child>
        <axis>
          <xyz>0 1 0</xyz>
          <limit>
            <effort>8.85</effort>
            <velocity>17.4</velocity>
            <lower>-1e+16</lower>
            <upper>1e+16</upper>
          </limit>
          <dynamics>
            <spring_reference>0</spring_reference>
            <spring_stiffness>0</spring_stiffness>
          </dynamics>
        </axis>
        <physics>
          <ode>
            <implicit_spring_damper>1</implicit_spring_damper>
            <cfm_damping>1</cfm_damping>
            <limit>
              <cfm>0</cfm>
              <erp>0.2</erp>
            </limit>
          </ode>
        </physics>
      </joint>
      <link name='r_wheel_link'>
        <pose relative_to='r_wheel_joint'>0 0 0 0 -0 0</pose>
        <inertial>
          <pose>0 0 0 0 -0 0</pose>
          <mass>4.3542</mass>
          <inertia>
            <ixx>0.0045</ixx>
            <ixy>0</ixy>
            <ixz>0</ixz>
            <iyy>0.005</iyy>
            <iyz>0</iyz>
            <izz>0.0045</izz>
          </inertia>
        </inertial>
        <collision name='r_wheel_link_collision'>
          <pose>0 0 0 0 -0 0</pose>
          <geometry>
            <mesh>
              <scale>1 1 1</scale>
              <uri>/home/ros/workspace/src/fetch_ros/fetch_description/meshes/r_wheel_link_collision.STL</uri>
            </mesh>
          </geometry>
          <surface>
            <contact>
              <ode>
                <kp>1e+06</kp>
                <kd>100</kd>
                <max_vel>1</max_vel>
                <min_depth>0.01</min_depth>
              </ode>
            </contact>
            <friction>
              <ode>
                <mu>1e+14</mu>
                <mu2>1e+14</mu2>
              </ode>
              <torsional>
                <ode/>
              </torsional>
            </friction>
            <bounce/>
          </surface>
          <max_contacts>10</max_contacts>
        </collision>
        <visual name='r_wheel_link_visual'>
          <pose>0 0 0 0 -0 0</pose>
          <geometry>
            <mesh>
              <scale>1 1 1</scale>
              <uri>/home/ros/workspace/src/fetch_ros/fetch_description/meshes/r_wheel_link.STL</uri>
            </mesh>
          </geometry>
          <material>
            <script>
              <name>Gazebo/Black</name>
              <uri>file://media/materials/scripts/gazebo.material</uri>
            </script>
          </material>
        </visual>
        <self_collide>0</self_collide>
        <enable_wind>0</enable_wind>
        <kinematic>0</kinematic>
      </link>
      <joint name='torso_lift_joint' type='prismatic'>
        <pose relative_to='base_link'>-0.086875 0 0.37743 0 -0 0</pose>
        <parent>base_link</parent>
        <child>torso_lift_link</child>
        <axis>
          <xyz>0 0 1</xyz>
          <limit>
            <lower>0</lower>
            <upper>0.38615</upper>
            <effort>450</effort>
            <velocity>0.1</velocity>
          </limit>
          <dynamics>
            <damping>100</damping>
            <friction>0</friction>
            <spring_reference>0</spring_reference>
            <spring_stiffness>0</spring_stiffness>
          </dynamics>
        </axis>
      </joint>
      <link name='torso_lift_link'>
        <pose relative_to='torso_lift_joint'>0 0 0 0 -0 0</pose>
        <inertial>
          <pose>-0.000984 -0.000886 0.286874 0 -0 0</pose>
          <mass>10.949</mass>
          <inertia>
            <ixx>0.36931</ixx>
            <ixy>-3.0664e-06</ixy>
            <ixz>-0.0147406</ixz>
            <iyy>0.367812</iyy>
            <iyz>-0.000535712</iyz>
            <izz>0.0971639</izz>
          </inertia>
        </inertial>
        <collision name='torso_lift_link_collision'>
          <pose>0 0 0 0 -0 0</pose>
          <geometry>
            <mesh>
              <scale>1 1 1</scale>
              <uri>/home/ros/workspace/src/fetch_ros/fetch_description/meshes/torso_lift_link_collision.STL</uri>
            </mesh>
          </geometry>
          <max_contacts>10</max_contacts>
          <surface>
            <contact>
              <ode/>
            </contact>
            <bounce/>
            <friction>
              <torsional>
                <ode/>
              </torsional>
              <ode/>
            </friction>
          </surface>
        </collision>
        <collision name='torso_lift_link_fixed_joint_lump__bellows_link2_collision_1'>
          <pose>0 0 0 0 -0 0</pose>
          <geometry>
            <mesh>
              <scale>1 1 1</scale>
              <uri>/home/ros/workspace/src/fetch_ros/fetch_description/meshes/bellows_link_collision.STL</uri>
            </mesh>
          </geometry>
          <surface>
            <contact>
              <ode/>
            </contact>
            <friction>
              <ode/>
              <torsional>
                <ode/>
              </torsional>
            </friction>
            <bounce/>
          </surface>
          <max_contacts>10</max_contacts>
        </collision>
        <visual name='torso_lift_link_visual'>
          <pose>0 0 0 0 -0 0</pose>
          <geometry>
            <mesh>
              <scale>1 1 1</scale>
              <uri>/home/ros/workspace/src/fetch_ros/fetch_description/meshes/torso_lift_link.dae</uri>
            </mesh>
          </geometry>
        </visual>
        <visual name='torso_lift_link_fixed_joint_lump__bellows_link2_visual_1'>
          <pose>0 0 0 0 -0 0</pose>
          <geometry>
            <mesh>
              <scale>1 1 1</scale>
              <uri>/home/ros/workspace/src/fetch_ros/fetch_description/meshes/bellows_link.STL</uri>
            </mesh>
          </geometry>
          <material>
            <script>
              <name>Gazebo/Black</name>
              <uri>file://media/materials/scripts/gazebo.material</uri>
            </script>
          </material>
        </visual>
        <self_collide>0</self_collide>
        <enable_wind>0</enable_wind>
        <kinematic>0</kinematic>
      </link>
      <joint name='bellows_joint' type='prismatic'>
        <pose relative_to='torso_lift_link'>0 0 0 0 -0 0</pose>
        <parent>torso_lift_link</parent>
        <child>bellows_link</child>
        <axis>
          <xyz>0 0 -1</xyz>
          <limit>
            <lower>0</lower>
            <upper>0.4</upper>
            <effort>5</effort>
            <velocity>0.1</velocity>
          </limit>
          <dynamics>
            <spring_reference>0</spring_reference>
            <spring_stiffness>0</spring_stiffness>
          </dynamics>
        </axis>
      </joint>
      <link name='bellows_link'>
        <pose relative_to='bellows_joint'>0 0 0 0 -0 0</pose>
        <inertial>
          <pose>0.019132 -0 -0.134862 0 -0 0</pose>
          <mass>0.169374</mass>
          <inertia>
            <ixx>0.00331159</ixx>
            <ixy>-8.9231e-18</ixy>
            <ixz>-5.38622e-08</ixz>
            <iyy>0.00174447</iyy>
            <iyz>-8.06965e-17</iyz>
            <izz>0.00169418</izz>
          </inertia>
        </inertial>
        <collision name='bellows_link_collision'>
          <pose>0 0 0 0 -0 0</pose>
          <geometry>
            <mesh>
              <scale>1 1 1</scale>
              <uri>/home/ros/workspace/src/fetch_ros/fetch_description/meshes/bellows_link_collision.STL</uri>
            </mesh>
          </geometry>
          <surface>
            <contact>
              <ode/>
            </contact>
            <friction>
              <ode/>
              <torsional>
                <ode/>
              </torsional>
            </friction>
            <bounce/>
          </surface>
          <max_contacts>10</max_contacts>
        </collision>
        <visual name='bellows_link_visual'>
          <pose>0 0 0 0 -0 0</pose>
          <geometry>
            <mesh>
              <scale>1 1 1</scale>
              <uri>/home/ros/workspace/src/fetch_ros/fetch_description/meshes/bellows_link.STL</uri>
            </mesh>
          </geometry>
          <material>
            <script>
              <name>Gazebo/Black</name>
              <uri>file://media/materials/scripts/gazebo.material</uri>
            </script>
          </material>
        </visual>
        <self_collide>0</self_collide>
        <enable_wind>0</enable_wind>
        <kinematic>0</kinematic>
      </link>
      <joint name='head_pan_joint' type='revolute'>
        <pose relative_to='torso_lift_link'>0.053125 0 0.603001 0 -0 0</pose>
        <parent>torso_lift_link</parent>
        <child>head_pan_link</child>
        <axis>
          <xyz>0 0 1</xyz>
          <limit>
            <lower>-1.57</lower>
            <upper>1.57</upper>
            <effort>0.32</effort>
            <velocity>1.57</velocity>
          </limit>
          <dynamics>
            <spring_reference>0</spring_reference>
            <spring_stiffness>0</spring_stiffness>
          </dynamics>
        </axis>
      </joint>
      <link name='head_pan_link'>
        <pose relative_to='head_pan_joint'>0 0 0 0 -0 0</pose>
        <inertial>
          <pose>0.0321 0.0161 0.039 0 -0 0</pose>
          <mass>2.2556</mass>
          <inertia>
            <ixx>0.0129</ixx>
            <ixy>0.0002</ixy>
            <ixz>0.0007</ixz>
            <iyy>0.0095</iyy>
            <iyz>0</iyz>
            <izz>0.0184</izz>
          </inertia>
        </inertial>
        <collision name='head_pan_link_collision'>
          <pose>0 0 0 0 -0 0</pose>
          <geometry>
            <mesh>
              <scale>1 1 1</scale>
              <uri>/home/ros/workspace/src/fetch_ros/fetch_description/meshes/head_pan_link_collision.STL</uri>
            </mesh>
          </geometry>
          <max_contacts>10</max_contacts>
          <surface>
            <contact>
              <ode/>
            </contact>
            <bounce/>
            <friction>
              <torsional>
                <ode/>
              </torsional>
              <ode/>
            </friction>
          </surface>
        </collision>
        <visual name='head_pan_link_visual'>
          <pose>0 0 0 0 -0 0</pose>
          <geometry>
            <mesh>
              <scale>1 1 1</scale>
              <uri>/home/ros/workspace/src/fetch_ros/fetch_description/meshes/head_pan_link.dae</uri>
            </mesh>
          </geometry>
        </visual>
        <self_collide>0</self_collide>
        <enable_wind>0</enable_wind>
        <kinematic>0</kinematic>
      </link>
      <joint name='head_tilt_joint' type='revolute'>
        <pose relative_to='head_pan_link'>0.14253 0 0.057999 0 -0 0</pose>
        <parent>head_pan_link</parent>
        <child>head_tilt_link</child>
        <axis>
          <xyz>0 1 0</xyz>
          <limit>
            <lower>-0.76</lower>
            <upper>1.45</upper>
            <effort>0.68</effort>
            <velocity>1.57</velocity>
          </limit>
          <dynamics>
            <spring_reference>0</spring_reference>
            <spring_stiffness>0</spring_stiffness>
          </dynamics>
        </axis>
      </joint>
      <link name='head_tilt_link'>
        <pose relative_to='head_tilt_joint'>0 0 0 0 -0 0</pose>
        <inertial>
          <pose>0.0081 0.0025 0.0113 0 -0 0</pose>
          <mass>0.9087</mass>
          <inertia>
            <ixx>0.0061</ixx>
            <ixy>0</ixy>
            <ixz>0.0002</ixz>
            <iyy>0.0014</iyy>
            <iyz>-0.0001</iyz>
            <izz>0.0061</izz>
          </inertia>
        </inertial>
        <collision name='head_tilt_link_collision'>
          <pose>0 0 0 0 -0 0</pose>
          <geometry>
            <mesh>
              <scale>1 1 1</scale>
              <uri>/home/ros/workspace/src/fetch_ros/fetch_description/meshes/head_tilt_link_collision.STL</uri>
            </mesh>
          </geometry>
          <max_contacts>10</max_contacts>
          <surface>
            <contact>
              <ode/>
            </contact>
            <bounce/>
            <friction>
              <torsional>
                <ode/>
              </torsional>
              <ode/>
            </friction>
          </surface>
        </collision>
        <visual name='head_tilt_link_visual'>
          <pose>0 0 0 0 -0 0</pose>
          <geometry>
            <mesh>
              <scale>1 1 1</scale>
              <uri>/home/ros/workspace/src/fetch_ros/fetch_description/meshes/head_tilt_link.dae</uri>
            </mesh>
          </geometry>
        </visual>
        <sensor name='camera' type='depth'>
          <always_on>1</always_on>
          <update_rate>15</update_rate>
          <camera>
            <horizontal_fov>1.0472</horizontal_fov>
            <image>
              <format>B8G8R8</format>
              <width>640</width>
              <height>480</height>
            </image>
            <clip>
              <near>0.05</near>
              <far>50</far>
            </clip>
          </camera>
          <plugin name='head_camera_controller' filename='libgazebo_ros_openni_kinect.so'>
            <baseline>0.1</baseline>
            <alwaysOn>1</alwaysOn>
            <updateRate>15.0</updateRate>
            <cameraName>head_camera</cameraName>
            <imageTopicName>/head_camera/rgb/image_raw</imageTopicName>
            <cameraInfoTopicName>/head_camera/rgb/camera_info</cameraInfoTopicName>
            <depthImageTopicName>/head_camera/depth_registered/image_raw</depthImageTopicName>
            <depthImageCameraInfoTopicName>/head_camera/depth_registered/camera_info</depthImageCameraInfoTopicName>
            <pointCloudTopicName>/head_camera/depth_registered/points</pointCloudTopicName>
            <frameName>head_camera_rgb_optical_frame</frameName>
            <pointCloudCutoff>0.35</pointCloudCutoff>
            <pointCloudCutoffMax>4.5</pointCloudCutoffMax>
            <CxPrime>0</CxPrime>
            <Cx>0</Cx>
            <Cy>0</Cy>
            <focalLength>0</focalLength>
            <hackBaseline>0</hackBaseline>
            <robotNamespace>/</robotNamespace>
          </plugin>
          <pose>0.055 0.02 0.0225 0 -0 0</pose>
        </sensor>
        <self_collide>0</self_collide>
        <enable_wind>0</enable_wind>
        <kinematic>0</kinematic>
      </link>
      <joint name='shoulder_pan_joint' type='revolute'>
        <pose relative_to='torso_lift_link'>0.119525 0 0.34858 0 -0 0</pose>
        <parent>torso_lift_link</parent>
        <child>shoulder_pan_link</child>
        <axis>
          <xyz>0 0 1</xyz>
          <limit>
            <lower>-1.6056</lower>
            <upper>1.6056</upper>
            <effort>33.82</effort>
            <velocity>1.256</velocity>
          </limit>
          <dynamics>
            <damping>1</damping>
            <friction>0</friction>
            <spring_reference>0</spring_reference>
            <spring_stiffness>0</spring_stiffness>
          </dynamics>
        </axis>
      </joint>
      <link name='shoulder_pan_link'>
        <pose relative_to='shoulder_pan_joint'>0 0 0 0 -0 0</pose>
        <inertial>
          <pose>0.0927 -0.0056 0.0564 0 -0 0</pose>
          <mass>2.5587</mass>
          <inertia>
            <ixx>0.0043</ixx>
            <ixy>-0.0001</ixy>
            <ixz>0.001</ixz>
            <iyy>0.0087</iyy>
            <iyz>-0.0001</iyz>
            <izz>0.0087</izz>
          </inertia>
        </inertial>
        <collision name='shoulder_pan_link_collision'>
          <pose>0 0 0 0 -0 0</pose>
          <geometry>
            <mesh>
              <scale>1 1 1</scale>
              <uri>/home/ros/workspace/src/fetch_ros/fetch_description/meshes/shoulder_pan_link_collision.STL</uri>
            </mesh>
          </geometry>
          <max_contacts>10</max_contacts>
          <surface>
            <contact>
              <ode/>
            </contact>
            <bounce/>
            <friction>
              <torsional>
                <ode/>
              </torsional>
              <ode/>
            </friction>
          </surface>
        </collision>
        <visual name='shoulder_pan_link_visual'>
          <pose>0 0 0 0 -0 0</pose>
          <geometry>
            <mesh>
              <scale>1 1 1</scale>
              <uri>/home/ros/workspace/src/fetch_ros/fetch_description/meshes/shoulder_pan_link.dae</uri>
            </mesh>
          </geometry>
        </visual>
        <self_collide>0</self_collide>
        <enable_wind>0</enable_wind>
        <kinematic>0</kinematic>
      </link>
      <joint name='shoulder_lift_joint' type='revolute'>
        <pose relative_to='shoulder_pan_link'>0.117 0 0.06 0 -0 0</pose>
        <parent>shoulder_pan_link</parent>
        <child>shoulder_lift_link</child>
        <axis>
          <xyz>0 1 0</xyz>
          <limit>
            <lower>-1.221</lower>
            <upper>1.518</upper>
            <effort>131.76</effort>
            <velocity>1.454</velocity>
          </limit>
          <dynamics>
            <damping>1</damping>
            <friction>0</friction>
            <spring_reference>0</spring_reference>
            <spring_stiffness>0</spring_stiffness>
          </dynamics>
        </axis>
      </joint>
      <link name='shoulder_lift_link'>
        <pose relative_to='shoulder_lift_joint'>0 0 0 0 -0 0</pose>
        <inertial>
          <pose>0.1432 0.0072 -0.0001 0 -0 0</pose>
          <mass>2.6615</mass>
          <inertia>
            <ixx>0.0028</ixx>
            <ixy>-0.0021</ixy>
            <ixz>0</ixz>
            <iyy>0.0111</iyy>
            <iyz>0</iyz>
            <izz>0.0112</izz>
          </inertia>
        </inertial>
        <collision name='shoulder_lift_link_collision'>
          <pose>0 0 0 0 -0 0</pose>
          <geometry>
            <mesh>
              <scale>1 1 1</scale>
              <uri>/home/ros/workspace/src/fetch_ros/fetch_description/meshes/shoulder_lift_link_collision.STL</uri>
            </mesh>
          </geometry>
          <max_contacts>10</max_contacts>
          <surface>
            <contact>
              <ode/>
            </contact>
            <bounce/>
            <friction>
              <torsional>
                <ode/>
              </torsional>
              <ode/>
            </friction>
          </surface>
        </collision>
        <visual name='shoulder_lift_link_visual'>
          <pose>0 0 0 0 -0 0</pose>
          <geometry>
            <mesh>
              <scale>1 1 1</scale>
              <uri>/home/ros/workspace/src/fetch_ros/fetch_description/meshes/shoulder_lift_link.dae</uri>
            </mesh>
          </geometry>
        </visual>
        <self_collide>0</self_collide>
        <enable_wind>0</enable_wind>
        <kinematic>0</kinematic>
      </link>
      <joint name='upperarm_roll_joint' type='revolute'>
        <pose relative_to='shoulder_lift_link'>0.219 0 0 0 -0 0</pose>
        <parent>shoulder_lift_link</parent>
        <child>upperarm_roll_link</child>
        <axis>
          <xyz>1 0 0</xyz>
          <limit>
            <effort>76.94</effort>
            <velocity>1.571</velocity>
            <lower>-1e+16</lower>
            <upper>1e+16</upper>
          </limit>
          <dynamics>
            <damping>5</damping>
            <friction>0</friction>
            <spring_reference>0</spring_reference>
            <spring_stiffness>0</spring_stiffness>
          </dynamics>
        </axis>
      </joint>
      <link name='upperarm_roll_link'>
        <pose relative_to='upperarm_roll_joint'>0 0 0 0 -0 0</pose>
        <inertial>
          <pose>0.1165 0.0014 0 0 -0 0</pose>
          <mass>2.3311</mass>
          <inertia>
            <ixx>0.0019</ixx>
            <ixy>-0.0001</ixy>
            <ixz>0</ixz>
            <iyy>0.0045</iyy>
            <iyz>0</iyz>
            <izz>0.0047</izz>
          </inertia>
        </inertial>
        <collision name='upperarm_roll_link_collision'>
          <pose>0 0 0 0 -0 0</pose>
          <geometry>
            <mesh>
              <scale>1 1 1</scale>
              <uri>/home/ros/workspace/src/fetch_ros/fetch_description/meshes/upperarm_roll_link_collision.STL</uri>
            </mesh>
          </geometry>
          <max_contacts>10</max_contacts>
          <surface>
            <contact>
              <ode/>
            </contact>
            <bounce/>
            <friction>
              <torsional>
                <ode/>
              </torsional>
              <ode/>
            </friction>
          </surface>
        </collision>
        <visual name='upperarm_roll_link_visual'>
          <pose>0 0 0 0 -0 0</pose>
          <geometry>
            <mesh>
              <scale>1 1 1</scale>
              <uri>/home/ros/workspace/src/fetch_ros/fetch_description/meshes/upperarm_roll_link.dae</uri>
            </mesh>
          </geometry>
        </visual>
        <self_collide>0</self_collide>
        <enable_wind>0</enable_wind>
        <kinematic>0</kinematic>
      </link>
      <joint name='elbow_flex_joint' type='revolute'>
        <pose relative_to='upperarm_roll_link'>0.133 0 0 0 -0 0</pose>
        <parent>upperarm_roll_link</parent>
        <child>elbow_flex_link</child>
        <axis>
          <xyz>0 1 0</xyz>
          <limit>
            <lower>-2.251</lower>
            <upper>2.251</upper>
            <effort>66.18</effort>
            <velocity>1.521</velocity>
          </limit>
          <dynamics>
            <damping>1</damping>
            <friction>0</friction>
            <spring_reference>0</spring_reference>
            <spring_stiffness>0</spring_stiffness>
          </dynamics>
        </axis>
      </joint>
      <link name='elbow_flex_link'>
        <pose relative_to='elbow_flex_joint'>0 0 0 0 -0 0</pose>
        <inertial>
          <pose>0.1279 0.0073 0 0 -0 0</pose>
          <mass>2.1299</mass>
          <inertia>
            <ixx>0.0024</ixx>
            <ixy>-0.0016</ixy>
            <ixz>0</ixz>
            <iyy>0.0082</iyy>
            <iyz>0</iyz>
            <izz>0.0084</izz>
          </inertia>
        </inertial>
        <collision name='elbow_flex_link_collision'>
          <pose>0 0 0 0 -0 0</pose>
          <geometry>
            <mesh>
              <scale>1 1 1</scale>
              <uri>/home/ros/workspace/src/fetch_ros/fetch_description/meshes/elbow_flex_link_collision.STL</uri>
            </mesh>
          </geometry>
          <max_contacts>10</max_contacts>
          <surface>
            <contact>
              <ode/>
            </contact>
            <bounce/>
            <friction>
              <torsional>
                <ode/>
              </torsional>
              <ode/>
            </friction>
          </surface>
        </collision>
        <visual name='elbow_flex_link_visual'>
          <pose>0 0 0 0 -0 0</pose>
          <geometry>
            <mesh>
              <scale>1 1 1</scale>
              <uri>/home/ros/workspace/src/fetch_ros/fetch_description/meshes/elbow_flex_link.dae</uri>
            </mesh>
          </geometry>
        </visual>
        <self_collide>0</self_collide>
        <enable_wind>0</enable_wind>
        <kinematic>0</kinematic>
      </link>
      <joint name='forearm_roll_joint' type='revolute'>
        <pose relative_to='elbow_flex_link'>0.197 0 0 0 -0 0</pose>
        <parent>elbow_flex_link</parent>
        <child>forearm_roll_link</child>
        <axis>
          <xyz>1 0 0</xyz>
          <limit>
            <effort>29.35</effort>
            <velocity>1.571</velocity>
            <lower>-1e+16</lower>
            <upper>1e+16</upper>
          </limit>
          <dynamics>
            <damping>5</damping>
            <friction>0</friction>
            <spring_reference>0</spring_reference>
            <spring_stiffness>0</spring_stiffness>
          </dynamics>
        </axis>
        <physics>
          <ode>
            <implicit_spring_damper>1</implicit_spring_damper>
            <cfm_damping>1</cfm_damping>
            <limit>
              <cfm>0</cfm>
              <erp>0.2</erp>
            </limit>
          </ode>
        </physics>
      </joint>
      <link name='forearm_roll_link'>
        <pose relative_to='forearm_roll_joint'>0 0 0 0 -0 0</pose>
        <inertial>
          <pose>0.1097 -0.0266 0 0 -0 0</pose>
          <mass>1.6563</mass>
          <inertia>
            <ixx>0.0016</ixx>
            <ixy>-0.0003</ixy>
            <ixz>0</ixz>
            <iyy>0.003</iyy>
            <iyz>0</iyz>
            <izz>0.0035</izz>
          </inertia>
        </inertial>
        <collision name='forearm_roll_link_collision'>
          <pose>0 0 0 0 -0 0</pose>
          <geometry>
            <mesh>
              <scale>1 1 1</scale>
              <uri>/home/ros/workspace/src/fetch_ros/fetch_description/meshes/forearm_roll_link_collision.STL</uri>
            </mesh>
          </geometry>
          <max_contacts>10</max_contacts>
          <surface>
            <contact>
              <ode/>
            </contact>
            <bounce/>
            <friction>
              <torsional>
                <ode/>
              </torsional>
              <ode/>
            </friction>
          </surface>
        </collision>
        <visual name='forearm_roll_link_visual'>
          <pose>0 0 0 0 -0 0</pose>
          <geometry>
            <mesh>
              <scale>1 1 1</scale>
              <uri>/home/ros/workspace/src/fetch_ros/fetch_description/meshes/forearm_roll_link.dae</uri>
            </mesh>
          </geometry>
        </visual>
        <self_collide>0</self_collide>
        <enable_wind>0</enable_wind>
        <kinematic>0</kinematic>
      </link>
      <joint name='wrist_flex_joint' type='revolute'>
        <pose relative_to='forearm_roll_link'>0.1245 0 0 0 -0 0</pose>
        <parent>forearm_roll_link</parent>
        <child>wrist_flex_link</child>
        <axis>
          <xyz>0 1 0</xyz>
          <limit>
            <lower>-2.16</lower>
            <upper>2.16</upper>
            <effort>25.7</effort>
            <velocity>2.268</velocity>
          </limit>
          <dynamics>
            <damping>1</damping>
            <friction>0</friction>
            <spring_reference>0</spring_reference>
            <spring_stiffness>0</spring_stiffness>
          </dynamics>
        </axis>
      </joint>
      <link name='wrist_flex_link'>
        <pose relative_to='wrist_flex_joint'>0 0 0 0 -0 0</pose>
        <inertial>
          <pose>0.0882 0.0009 -0.0001 0 -0 0</pose>
          <mass>1.725</mass>
          <inertia>
            <ixx>0.0018</ixx>
            <ixy>-0.0001</ixy>
            <ixz>0</ixz>
            <iyy>0.0042</iyy>
            <iyz>0</iyz>
            <izz>0.0042</izz>
          </inertia>
        </inertial>
        <collision name='wrist_flex_link_collision'>
          <pose>0 0 0 0 -0 0</pose>
          <geometry>
            <mesh>
              <scale>1 1 1</scale>
              <uri>/home/ros/workspace/src/fetch_ros/fetch_description/meshes/wrist_flex_link_collision.STL</uri>
            </mesh>
          </geometry>
          <max_contacts>10</max_contacts>
          <surface>
            <contact>
              <ode/>
            </contact>
            <bounce/>
            <friction>
              <torsional>
                <ode/>
              </torsional>
              <ode/>
            </friction>
          </surface>
        </collision>
        <visual name='wrist_flex_link_visual'>
          <pose>0 0 0 0 -0 0</pose>
          <geometry>
            <mesh>
              <scale>1 1 1</scale>
              <uri>/home/ros/workspace/src/fetch_ros/fetch_description/meshes/wrist_flex_link.dae</uri>
            </mesh>
          </geometry>
        </visual>
        <self_collide>0</self_collide>
        <enable_wind>0</enable_wind>
        <kinematic>0</kinematic>
      </link>
      <joint name='wrist_roll_joint' type='revolute'>
        <pose relative_to='wrist_flex_link'>0.1385 0 0 0 -0 0</pose>
        <parent>wrist_flex_link</parent>
        <child>wrist_roll_link</child>
        <axis>
          <xyz>1 0 0</xyz>
          <limit>
            <effort>7.36</effort>
            <velocity>2.268</velocity>
            <lower>-1e+16</lower>
            <upper>1e+16</upper>
          </limit>
          <dynamics>
            <damping>5</damping>
            <friction>0</friction>
            <spring_reference>0</spring_reference>
            <spring_stiffness>0</spring_stiffness>
          </dynamics>
        </axis>
        <physics>
          <ode>
            <implicit_spring_damper>1</implicit_spring_damper>
            <cfm_damping>1</cfm_damping>
            <limit>
              <cfm>0</cfm>
              <erp>0.2</erp>
            </limit>
          </ode>
        </physics>
      </joint>
      <link name='wrist_roll_link'>
        <pose relative_to='wrist_roll_joint'>0 0 0 0 -0 0</pose>
        <inertial>
          <pose>0.070966 -5.9e-05 -0.001577 0 -0 0</pose>
          <mass>1.6529</mass>
          <inertia>
            <ixx>0.00140031</ixx>
            <ixy>4.16123e-06</ixy>
            <ixz>1.24837e-05</ixz>
            <iyy>0.00255747</iyy>
            <iyz>-9.32314e-08</iyz>
            <izz>0.00305722</izz>
          </inertia>
        </inertial>
        <collision name='wrist_roll_link_collision'>
          <pose>0 0 0 0 -0 0</pose>
          <geometry>
            <mesh>
              <scale>1 1 1</scale>
              <uri>/home/ros/workspace/src/fetch_ros/fetch_description/meshes/wrist_roll_link_collision.STL</uri>
            </mesh>
          </geometry>
          <max_contacts>10</max_contacts>
          <surface>
            <contact>
              <ode/>
            </contact>
            <bounce/>
            <friction>
              <torsional>
                <ode/>
              </torsional>
              <ode/>
            </friction>
          </surface>
        </collision>
        <collision name='wrist_roll_link_fixed_joint_lump__gripper_link_collision_1'>
          <pose>0.16645 0 0 0 -0 0</pose>
          <geometry>
            <mesh>
              <scale>1 1 1</scale>
              <uri>/home/ros/workspace/src/fetch_ros/fetch_description/meshes/gripper_link.STL</uri>
            </mesh>
          </geometry>
          <max_contacts>10</max_contacts>
          <surface>
            <contact>
              <ode/>
            </contact>
            <bounce/>
            <friction>
              <torsional>
                <ode/>
              </torsional>
              <ode/>
            </friction>
          </surface>
        </collision>
        <visual name='wrist_roll_link_visual'>
          <pose>0 0 0 0 -0 0</pose>
          <geometry>
            <mesh>
              <scale>1 1 1</scale>
              <uri>/home/ros/workspace/src/fetch_ros/fetch_description/meshes/wrist_roll_link.dae</uri>
            </mesh>
          </geometry>
        </visual>
        <visual name='wrist_roll_link_fixed_joint_lump__gripper_link_visual_1'>
          <pose>0.16645 0 0 0 -0 0</pose>
          <geometry>
            <mesh>
              <scale>1 1 1</scale>
              <uri>/home/ros/workspace/src/fetch_ros/fetch_description/meshes/gripper_link.dae</uri>
            </mesh>
          </geometry>
        </visual>
        <self_collide>0</self_collide>
        <enable_wind>0</enable_wind>
        <kinematic>0</kinematic>
      </link>
      <joint name='l_gripper_finger_joint' type='prismatic'>
        <pose relative_to='wrist_roll_link'>0.16645 -0.015425 0 0 -0 0</pose>
        <parent>wrist_roll_link</parent>
        <child>l_gripper_finger_link</child>
        <axis>
          <xyz>0 -1 0</xyz>
          <limit>
            <lower>0</lower>
            <upper>0.05</upper>
            <effort>60</effort>
            <velocity>0.05</velocity>
          </limit>
          <dynamics>
            <damping>100</damping>
            <friction>0</friction>
            <spring_reference>0</spring_reference>
            <spring_stiffness>0</spring_stiffness>
          </dynamics>
        </axis>
      </joint>
      <link name='l_gripper_finger_link'>
        <pose relative_to='l_gripper_finger_joint'>0 0 0 0 -0 0</pose>
        <inertial>
          <pose>-0.01 0 0 0 -0 0</pose>
          <mass>0.0798</mass>
          <inertia>
            <ixx>0.002</ixx>
            <ixy>0</ixy>
            <ixz>0</ixz>
            <iyy>0</iyy>
            <iyz>0</iyz>
            <izz>0</izz>
          </inertia>
        </inertial>
        <collision name='l_gripper_finger_link_collision'>
          <pose>0 -0.101425 0 0 -0 0</pose>
          <geometry>
            <mesh>
              <scale>1 1 1</scale>
              <uri>/home/ros/workspace/src/fetch_ros/fetch_description/meshes/l_gripper_finger_link.STL</uri>
            </mesh>
          </geometry>
          <surface>
            <contact>
              <ode>
                <kp>1e+06</kp>
                <kd>100</kd>
                <max_vel>1</max_vel>
                <min_depth>0.001</min_depth>
              </ode>
            </contact>
            <friction>
              <ode>
                <mu>30</mu>
                <mu2>30</mu2>
              </ode>
              <torsional>
                <ode/>
              </torsional>
            </friction>
            <bounce/>
          </surface>
          <max_contacts>10</max_contacts>
        </collision>
        <visual name='l_gripper_finger_link_visual'>
          <pose>0 -0.101425 0 0 -0 0</pose>
          <geometry>
            <mesh>
              <scale>1 1 1</scale>
              <uri>/home/ros/workspace/src/fetch_ros/fetch_description/meshes/l_gripper_finger_link.STL</uri>
            </mesh>
          </geometry>
          <material>
            <script>
              <name>Gazebo/Grey</name>
              <uri>file://media/materials/scripts/gazebo.material</uri>
            </script>
          </material>
        </visual>
        <self_collide>0</self_collide>
        <enable_wind>0</enable_wind>
        <kinematic>0</kinematic>
      </link>
      <joint name='r_gripper_finger_joint' type='prismatic'>
        <pose relative_to='wrist_roll_link'>0.16645 0.015425 0 0 -0 0</pose>
        <parent>wrist_roll_link</parent>
        <child>r_gripper_finger_link</child>
        <axis>
          <xyz>0 1 0</xyz>
          <limit>
            <lower>0</lower>
            <upper>0.05</upper>
            <effort>60</effort>
            <velocity>0.05</velocity>
          </limit>
          <dynamics>
            <damping>100</damping>
            <friction>0</friction>
            <spring_reference>0</spring_reference>
            <spring_stiffness>0</spring_stiffness>
          </dynamics>
        </axis>
      </joint>
      <link name='r_gripper_finger_link'>
        <pose relative_to='r_gripper_finger_joint'>0 0 0 0 -0 0</pose>
        <inertial>
          <pose>-0.01 0 0 0 -0 0</pose>
          <mass>0.0798</mass>
          <inertia>
            <ixx>0.002</ixx>
            <ixy>0</ixy>
            <ixz>0</ixz>
            <iyy>0</iyy>
            <iyz>0</iyz>
            <izz>0</izz>
          </inertia>
        </inertial>
        <collision name='r_gripper_finger_link_collision'>
          <pose>0 0.101425 0 0 -0 0</pose>
          <geometry>
            <mesh>
              <scale>1 1 1</scale>
              <uri>/home/ros/workspace/src/fetch_ros/fetch_description/meshes/r_gripper_finger_link.STL</uri>
            </mesh>
          </geometry>
          <surface>
            <contact>
              <ode>
                <kp>1e+06</kp>
                <kd>100</kd>
                <max_vel>1</max_vel>
                <min_depth>0.001</min_depth>
              </ode>
            </contact>
            <friction>
              <ode>
                <mu>30</mu>
                <mu2>30</mu2>
              </ode>
              <torsional>
                <ode/>
              </torsional>
            </friction>
            <bounce/>
          </surface>
          <max_contacts>10</max_contacts>
        </collision>
        <visual name='r_gripper_finger_link_visual'>
          <pose>0 0.101425 0 0 -0 0</pose>
          <geometry>
            <mesh>
              <scale>1 1 1</scale>
              <uri>/home/ros/workspace/src/fetch_ros/fetch_description/meshes/r_gripper_finger_link.STL</uri>
            </mesh>
          </geometry>
          <material>
            <script>
              <name>Gazebo/Grey</name>
              <uri>file://media/materials/scripts/gazebo.material</uri>
            </script>
          </material>
        </visual>
        <self_collide>0</self_collide>
        <enable_wind>0</enable_wind>
        <kinematic>0</kinematic>
      </link>
      <static>0</static>
      <plugin name='fetch_gazebo_plugin' filename='libfetch_gazebo_plugin.so'>
        <robotNamespace>/</robotNamespace>
      </plugin>
      <pose>0 0 0 0 -0 0</pose>
    </model>
    <model name='pot'>
      <static>1</static>
      <link name='link'>
        <collision name='collision'>
          <geometry>
            <mesh>
              <uri>model://pot/meshes/model.stl</uri>
            </mesh>
          </geometry>
          <max_contacts>10</max_contacts>
          <surface>
            <contact>
              <ode/>
            </contact>
            <bounce/>
            <friction>
              <torsional>
                <ode/>
              </torsional>
              <ode/>
            </friction>
          </surface>
        </collision>
        <visual name='visual'>
          <geometry>
            <mesh>
              <uri>model://pot/meshes/model.stl</uri>
            </mesh>
          </geometry>
          <material>
            <ambient>1 1 1 1</ambient>
            <diffuse>1 1 1 1</diffuse>
            <specular>0.1 0.1 0.1 1</specular>
            <emissive>0 0 0 1</emissive>
          </material>
        </visual>
        <self_collide>0</self_collide>
        <enable_wind>0</enable_wind>
        <kinematic>0</kinematic>
      </link>
      <pose>1.20009 0.392651 0 0 -0 0</pose>
    </model>
    <model name='carrot'>
      <static>0</static>
      <link name='link'>
        <inertial>
          <mass>0.25</mass>
          <inertia>
            <ixx>0.001</ixx>
            <ixy>0</ixy>
            <ixz>0</ixz>
            <iyy>0.001</iyy>
            <iyz>0</iyz>
            <izz>0.001</izz>
          </inertia>
          <pose>0 0 0 0 -0 0</pose>
        </inertial>
        <collision name='collision'>
          <geometry>
            <box>
              <size>0.06 0.06 0.06</size>
            </box>
          </geometry>
          <surface>
            <friction>
              <ode>
                <mu>30</mu>
                <mu2>30</mu2>
              </ode>
              <torsional>
                <ode/>
              </torsional>
            </friction>
            <contact>
              <ode>
                <kp>1e+06</kp>
                <kd>100</kd>
                <max_vel>1</max_vel>
                <min_depth>0.002</min_depth>
              </ode>
            </contact>
            <bounce/>
          </surface>
          <max_contacts>10</max_contacts>
        </collision>
        <visual name='visual'>
          <geometry>
            <box>
              <size>0.06 0.06 0.06</size>
            </box>
          </geometry>
          <material>
            <script>
              <uri>file://media/materials/scripts/gazebo.material</uri>
              <name>Gazebo/Orange</name>
            </script>
          </material>
        </visual>
        <velocity_decay>
          <linear>0</linear>
          <angular>0</angular>
        </velocity_decay>
        <self_collide>0</self_collide>
        <kinematic>0</kinematic>
        <gravity>1</gravity>
        <enable_wind>0</enable_wind>
      </link>
      <pose>0.55257 -0.401544 0 0 -0 0</pose>
    </model>
    <model name='fish'>
      <static>0</static>
      <link name='link'>
        <inertial>
          <mass>0.25</mass>
          <inertia>
            <ixx>0.001</ixx>
            <ixy>0</ixy>
            <ixz>0</ixz>
            <iyy>0.001</iyy>
            <iyz>0</iyz>
            <izz>0.001</izz>
          </inertia>
          <pose>0 0 0 0 -0 0</pose>
        </inertial>
        <collision name='collision'>
          <geometry>
            <box>
              <size>0.06 0.06 0.06</size>
            </box>
          </geometry>
          <surface>
            <friction>
              <ode>
                <mu>30</mu>
                <mu2>30</mu2>
              </ode>
              <torsional>
                <ode/>
              </torsional>
            </friction>
            <contact>
              <ode>
                <kp>1e+06</kp>
                <kd>100</kd>
                <max_vel>1</max_vel>
                <min_depth>0.002</min_depth>
              </ode>
            </contact>
            <bounce/>
          </surface>
          <max_contacts>10</max_contacts>
        </collision>
        <visual name='visual'>
          <geometry>
            <box>
              <size>0.06 0.06 0.06</size>
            </box>
          </geometry>
          <material>
            <script>
              <uri>file://media/materials/scripts/gazebo.material</uri>
              <name>Gazebo/Pink</name>
            </script>
          </material>
        </visual>
        <velocity_decay>
          <linear>0</linear>
          <angular>0</angular>
        </velocity_decay>
        <self_collide>0</self_collide>
        <kinematic>0</kinematic>
        <gravity>1</gravity>
        <enable_wind>0</enable_wind>
      </link>
      <pose>0.698154 -0.401323 0 0 -0 0</pose>
    </model>
    <model name='salt'>
      <static>0</static>
      <link name='link'>
        <inertial>
          <mass>0.25</mass>
          <inertia>
            <ixx>0.001</ixx>
            <ixy>0</ixy>
            <ixz>0</ixz>
            <iyy>0.001</iyy>
            <iyz>0</iyz>
            <izz>0.001</izz>
          </inertia>
          <pose>0 0 0 0 -0 0</pose>
        </inertial>
        <collision name='collision'>
          <geometry>
            <box>
              <size>0.06 0.06 0.06</size>
            </box>
          </geometry>
          <surface>
            <friction>
              <ode>
                <mu>30</mu>
                <mu2>30</mu2>
              </ode>
              <torsional>
                <ode/>
              </torsional>
            </friction>
            <contact>
              <ode>
                <kp>1e+06</kp>
                <kd>100</kd>
                <max_vel>1</max_vel>
                <min_depth>0.002</min_depth>
              </ode>
            </contact>
            <bounce/>
          </surface>
          <max_contacts>10</max_contacts>
        </collision>
        <visual name='visual'>
          <geometry>
            <box>
              <size>0.06 0.06 0.06</size>
            </box>
          </geometry>
          <material>
            <script>
              <uri>file://media/materials/scripts/gazebo.material</uri>
              <name>Gazebo/White</name>
            </script>
          </material>
        </visual>
        <velocity_decay>
          <linear>0</linear>
          <angular>0</angular>
        </velocity_decay>
        <self_collide>0</self_collide>
        <kinematic>0</kinematic>
        <gravity>1</gravity>
        <enable_wind>0</enable_wind>
      </link>
      <pose>0.847048 -0.392128 0 0 -0 0</pose>
    </model>
    <state world_name='default'>
      <sim_time>224 546000000</sim_time>
      <real_time>235 962839062</real_time>
      <wall_time>1730036859 271630837</wall_time>
      <iterations>224546</iterations>
      <model name='carrot'>
        <pose>0.55257 -0.24635 0.384595 0 -0 0</pose>
        <scale>1 1 1</scale>
        <link name='link'>
          <pose>0.55257 -0.24635 0.384595 0 -0 0</pose>
          <velocity>0 0 0 0 -0 0</velocity>
          <acceleration>0 0 -0 0 -0 0</acceleration>
          <wrench>0 0 -0 0 -0 0</wrench>
        </link>
      </model>
      <model name='fetch'>
        <pose>-2e-06 0 0.004772 -9e-06 1e-06 0</pose>
        <scale>1 1 1</scale>
        <link name='base_link'>
          <pose>-2e-06 0 0.004772 -9e-06 1e-06 0</pose>
          <velocity>-3e-06 2e-06 0.000115 -0.000443 -0.000638 -0</velocity>
          <acceleration>-0.143605 0.027383 -0.189619 -0.252819 -1.32587 -7e-06</acceleration>
          <wrench>-11.9848 2.28533 -15.8251 0 -0 0</wrench>
        </link>
        <link name='bellows_link'>
          <pose>-0.086877 3e-06 0.375565 -9e-06 1e-06 0</pose>
          <velocity>-0.000188 0.000161 -0.000487 -0.000485 -0.001026 2.1e-05</velocity>
          <acceleration>-0.107188 0.042016 -0.081679 2.81218 -1.02997 -3.10182</acceleration>
          <wrench>-0.018155 0.007116 -0.013834 0 -0 0</wrench>
        </link>
        <link name='elbow_flex_link'>
          <pose>0.128503 0.374141 0.564 -9.7e-05 -1.29998 1.3201</pose>
          <velocity>0.009344 -0.005188 -0.001197 -0.018209 -0.057667 0.014561</velocity>
          <acceleration>4.04421 -3.53386 -1.19653 -0.648561 -1.39454 -2.23617</acceleration>
          <wrench>8.61377 -7.52677 -2.54848 0 -0 0</wrench>
        </link>
        <link name='forearm_roll_link'>
          <pose>0.141575 0.425194 0.75382 0.000117 -1.29998 1.3201</pose>
          <velocity>-0.006159 -0.001266 -0.000273 0.007234 0.052877 0.415721</velocity>
          <acceleration>-19.397 23.2704 -0.698261 2.13518 0.580168 2.81487</acceleration>
          <wrench>-32.1272 38.5428 -1.15653 0 -0 0</wrench>
        </link>
        <link name='head_pan_link'>
          <pose>-0.033751 9e-06 0.985197 -9e-06 1e-06 -2.9e-05</pose>
          <velocity>-0.000762 0.000453 0.001684 -0.000479 -0.000944 -0.002679</velocity>
          <acceleration>-1.60809 0.210455 -0.504807 2.81969 -1.19711 0.53263</acceleration>
          <wrench>-3.62721 0.474703 -1.13864 0 -0 0</wrench>
        </link>
        <link name='head_tilt_link'>
          <pose>0.108779 5e-06 1.0432 -9e-06 0.002439 -2.9e-05</pose>
          <velocity>-0.000818 9.9e-05 0.001818 -0.000478 0.026983 -0.002681</velocity>
          <acceleration>-1.62209 -0.089916 -0.331082 -0.317119 -0.817646 -2.6139</acceleration>
          <wrench>-1.474 -0.081706 -0.300854 0 -0 0</wrench>
        </link>
        <link name='l_gripper_finger_link'>
          <pose>0.190942 0.354139 1.16518 3.1415 -1.27163 -1.82158</pose>
          <velocity>0.156219 -0.043432 -0.000442 0.000773 -0.004276 -0.001509</velocity>
          <acceleration>312.474 -87.0919 2.26453 -1.24468 1.25963 -0.491166</acceleration>
          <wrench>24.9355 -6.94993 0.18071 0 -0 0</wrench>
        </link>
        <link name='l_wheel_link'>
          <pose>0.001289 0.187381 0.060095 -9e-06 -0.134358 1e-06</pose>
          <velocity>-4.1e-05 2.7e-05 3.2e-05 -0.000443 0.000703 1e-06</velocity>
          <acceleration>-0.084743 0.015602 -0.196113 -0.255528 -0 0.002936</acceleration>
          <wrench>-0.368987 0.067935 -0.853915 0 -0 0</wrench>
        </link>
        <link name='r_gripper_finger_link'>
          <pose>0.064131 0.386637 1.16519 3.14147 -1.27163 -1.82155</pose>
          <velocity>-0.168501 0.040489 4e-05 0.001652 0.014097 0.001911</velocity>
          <acceleration>-337.326 80.8112 3.23369 0 -0 0</acceleration>
          <wrench>-26.9186 6.44873 0.258048 0 -0 0</wrench>
        </link>
        <link name='r_wheel_link'>
          <pose>0.001289 -0.187379 0.060099 -9e-06 0.1486 -1e-06</pose>
          <velocity>-4e-05 2.7e-05 0.0002 -0.000444 0.000716 2e-06</velocity>
          <acceleration>-0.083717 0.015616 -0.100691 -0.255248 0 0.002998</acceleration>
          <wrench>-0.364519 0.067994 -0.438428 0 -0 0</wrench>
        </link>
        <link name='shoulder_lift_link'>
          <pose>0.061687 0.113347 0.790774 -2e-06 0.700035 1.31999</pose>
          <velocity>0.001831 -0.000184 0.001773 -0.013356 -0.005726 -0.019282</velocity>
          <acceleration>9.27989 -2.23866 -0.653411 0.970765 -1.5208 -2.43476</acceleration>
          <wrench>24.6984 -5.95819 -1.73905 0 -0 0</wrench>
        </link>
        <link name='shoulder_pan_link'>
          <pose>0.032649 7e-06 0.730775 1e-06 7e-06 1.31999</pose>
          <velocity>-0.001168 0.000519 0.001878 -0.000278 0.002225 -0.019842</velocity>
          <acceleration>1.36696 -0.552012 -0.280574 -0.594233 -0.576339 -0.928394</acceleration>
          <wrench>3.49765 -1.41243 -0.717905 0 -0 0</wrench>
        </link>
        <link name='torso_lift_link'>
          <pose>-0.086877 3e-06 0.382196 -9e-06 1e-06 0</pose>
          <velocity>-0.000234 0.000168 0.001632 -0.000455 -0.000736 -2.2e-05</velocity>
          <acceleration>-0.923298 0.174534 -0.670722 -0.277176 -1.52132 -0.042957</acceleration>
          <wrench>-10.1092 1.91097 -7.34374 0 -0 0</wrench>
        </link>
        <link name='upperarm_roll_link'>
          <pose>0.103258 0.275602 0.649684 -3.1e-05 0.700035 1.31999</pose>
          <velocity>0.00728 -0.003313 -0.000127 -0.024557 -0.050077 0.016623</velocity>
          <acceleration>20.2239 -5.73776 -0.903729 0.237178 0.290299 -2.23622</acceleration>
          <wrench>47.1438 -13.3753 -2.10668 0 -0 0</wrench>
        </link>
        <link name='wrist_flex_link'>
          <pose>0.149836 0.45746 0.873782 3.14154 -1.2716 -1.82134</pose>
          <velocity>-0.01755 0.00227 -0.000298 0.01085 0.02074 0.403325</velocity>
          <acceleration>-11.6824 -3.53222 2.2652 -0.349246 -0.578449 1.9643</acceleration>
          <wrench>-20.1521 -6.09308 3.90747 0 -0 0</wrench>
        </link>
        <link name='wrist_roll_link'>
          <pose>0.139712 0.417913 1.00613 3.1413 -1.2716 -1.82138</pose>
          <velocity>-0.005636 -0.001416 -0.00039 0.034814 0.113196 0.011719</velocity>
          <acceleration>4.52306 -8.00022 2.10091 -1.16984 -0.562691 1.31424</acceleration>
          <wrench>7.47616 -13.2236 3.4726 0 -0 0</wrench>
        </link>
      </model>
      <model name='fish'>
        <pose>0.695635 -0.111153 0.384595 0 -0 0</pose>
        <scale>1 1 1</scale>
        <link name='link'>
          <pose>0.695635 -0.111153 0.384595 0 -0 0</pose>
          <velocity>0 0 0 0 -0 0</velocity>
          <acceleration>-0 -0 0 0 -0 0</acceleration>
          <wrench>-0 -0 0 0 -0 0</wrench>
        </link>
      </model>
      <model name='ground_plane'>
        <pose>0 0 0 0 -0 0</pose>
        <scale>1 1 1</scale>
        <link name='link'>
          <pose>0 0 0 0 -0 0</pose>
          <velocity>0 0 0 0 -0 0</velocity>
          <acceleration>0 0 0 0 -0 0</acceleration>
          <wrench>0 0 0 0 -0 0</wrench>
        </link>
      </model>
      <model name='pot'>
        <pose>0.601428 0.139912 0.359878 0 0 -1.37969</pose>
        <scale>1 1 1</scale>
        <link name='link'>
          <pose>0.601428 0.139912 0.359878 0 0 -1.37969</pose>
          <velocity>0 0 0 0 -0 0</velocity>
          <acceleration>0 0 0 0 -0 0</acceleration>
          <wrench>0 0 0 0 -0 0</wrench>
        </link>
      </model>
      <model name='salt'>
        <pose>0.847048 -0.259418 0.384595 0 -0 0</pose>
        <scale>1 1 1</scale>
        <link name='link'>
          <pose>0.847048 -0.259418 0.384595 0 -0 0</pose>
          <velocity>0 0 0 0 -0 0</velocity>
          <acceleration>-0 -0 0 0 -0 0</acceleration>
          <wrench>-0 -0 0 0 -0 0</wrench>
        </link>
      </model>
      <model name='table1'>
        <pose>0.87589 0 -0.418405 0 -0 0</pose>
        <scale>1 1 1</scale>
        <link name='link'>
          <pose>0.87589 0 -0.418405 0 -0 0</pose>
          <velocity>0 0 0 0 -0 0</velocity>
          <acceleration>0 0 0 0 -0 0</acceleration>
          <wrench>0 0 0 0 -0 0</wrench>
        </link>
      </model>
      <light name='sun'>
        <pose>0 0 10 0 -0 0</pose>
      </light>
    </state>
    <gui fullscreen='0'>
      <camera name='user_camera'>
        <pose>1.6897 -2.73724 3.09612 0 0.687643 1.8682</pose>
        <view_controller>orbit</view_controller>
        <projection_type>perspective</projection_type>
      </camera>
    </gui>
  </world>
</sdf>
